Workbook
Name DanToc: OFFSET(DynamicData!$F$2,0,0,COUNTA(DynamicData!$F:$F)-1,1)
Name DeNghi: OFFSET(DynamicData!$Q$2,0,0,COUNTA(DynamicData!$Q:$Q)-1,1)
Name DiaDiemKham: OFFSET(DynamicData!$D$2,0,0,COUNTA(DynamicData!$D:$D)-1,1)
Name DS_TRUONG: #REF!
Name HinhThucChiTra: OFFSET(DynamicData!$H$2,0,0,COUNTA(DynamicData!$H:$H)-1,1)
Name HinhThucKham: OFFSET(DynamicData!$J$2,0,0,COUNTA(DynamicData!$J:$J)-1,1)
Name NgheNghiep: OFFSET(NgheNghiep!$A$2,0,0,COUNTA(NgheNghiep!$A:$A)-1,1)
Name NOI_CONG_TAC_WARD_BY_CITY: OFFSET(INDIRECT("WARD[wardName]"),MATCH(ThongTinHanhChinh!$GI1,INDIRECT("WARD[CityId]"),0)-1,0,COUNTIF(INDIRECT("WARD[CityId]"),ThongTinHanhChinh!$GI1),1)
Name NoiLamViec: OFFSET(NoiLamViec!$A$2,0,0,COUNTA(NoiLamViec!$A:$A)-1,1)
Name Tinh: OFFSET(Tinh!$A$2,0,0,COUNTA(Tinh!$A:$A)-1,1)
Name TRUONG: OFFSET(#REF!,MATCH(ThongTinHanhChinh!#REF!,#REF!,0)-1,0,COUNTIF(#REF!,ThongTinHanhChinh!#REF!),1)
Name WARD_BY_CITY: OFFSET(INDIRECT("WARD[wardName]"),MATCH(ThongTinHanhChinh!$GG1,INDIRECT("WARD[CityId]"),0)-1,0,COUNTIF(INDIRECT("WARD[CityId]"),ThongTinHanhChinh!$GG1),1)

Sheet ThongTinHanhChinh
B1: Chỉ nhập mã phiếu với trường hợp cập nhật Nhập mã phiếu để xác định phiếu cần cập nhật. Không nhập mã phiếu, lấy phiếu chưa xóa có ngày khám mới nhất để cập nhật | C1: Nhập dạng (dd/MM/yyyy) - Đối với Import cập nhật không cần nhập cột này | D1: Nhập theo mã đối tượng ở sheet đối tượng. Nếu nhập nhiều đối tượng Ví dụ: 1, 2, 3 - Đối với Import cập nhật không cần nhập cột này | E1: - Đối với Import cập nhật không cần nhập cột này | F1: Nhập CCCD 12 số | H1: Nhập dạng dd/MM/yyyy | I1: 1: Nam 2: Nữ 3: Chưa xác định | J1: Nhập từ danh mục dân tộc | K1: A : Nhóm máu A B : Nhóm máu B O : Nhóm máu O AB: Nhóm máu AB | L1: 1: Rh- 2: Rh+ | N1: - Đối với Import cập nhật không cần nhập cột này | O1: - Đối với Import cập nhật không cần nhập cột này | P1: - Đối với Update không cần nhập cột này | Q1: Chọn từ danh mục xã phường - Đối với Update không cần nhập cột này | R1: Chọn nghề nghiệp ở bên danh mục hoặc qua sheet danh mục copy tên nghề nghiệp dán vào ô nhập liệu | S1: Nhập mã từ sheet NoiLamViec Nếu không có mã, vui lòng lấy mã tại cột "Mã import Đơn vị" trên PM ở MH danh sách Nơi làm việc/ học tập | W1: 1 - Đồng ý xét nghiệm 2 - Sử dụng kết quả xét nghiệm sẵn có 3 - Từ chối xét nghiệm - Đối với import cập nhật không cần nhập cột này | X1: Nhập theo danh mục - Đối với import cập nhật không cần nhập cột này | Y1: Nhập theo danh mục - Đối với import cập nhật không cần nhập cột này | Z1: Nếu chọn hình thức khám là nguồn khác | AA1: Nhập Theo Danh Mục ID ở sheet Bệnh Tiền Sử Gia Đình. Ví dụ nhiều bệnh cách nay bằng dấu phẩy. VD: 1051, 1052 | AB1: Nhập icd (Nếu nhiều mã cách nhau bởi dấu phẩy) | AC1: Tiền sử bệnh, tật của bản thân 1 - Có 0 - Không - Đối với Import cập nhật không cần nhập cột này | AX1: Nhập tự do | AY1: 1 - Có 0 - Không Nhập số | BA1: 1 - Có 0 - Không Nhập số | BC1: - Đối với Import cập nhật không cần nhập cột này | BI1: 1 - Loại 1 2 - Loại 2 3 - Loại 3 4 - Loại 4 5 - Loại 5 - Đối với Import cập nhật không cần nhập cột này | BJ1: 1 - Chưa phát hiện bất thường (Có đánh giấu vào ô) 0 - Phát hiện bất thường (Không đánh giấu ô) | BK1: Nhập Mã ICD, nếu nhiều mã cách nhau bằng dấu phẩy | BL1: Nhập Mã ICD, nếu nhiều mã cách nhau bằng dấu phẩy | BM1: 1 - Loại 1 2 - Loại 2 3 - Loại 3 4 - Loại 4 5 - Loại 5 - Đối với Import cập nhật không cần nhập cột này | BN1: 1 - Chưa phát hiện bất thường (Có đánh giấu vào ô) 0 - Phát hiện bất thường (Không đánh giấu ô) | BO1: Nhập Mã ICD, nếu nhiều mã cách nhau bằng dấu phẩy | BP1: Nhập Mã ICD, nếu nhiều mã cách nhau bằng dấu phẩy | BQ1: 1 - Loại 1 2 - Loại 2 3 - Loại 3 4 - Loại 4 5 - Loại 5 - Đối với Import cập nhật không cần nhập cột này | BR1: 1 - Chưa phát hiện bất thường (Có đánh giấu vào ô) 0 - Phát hiện bất thường (Không đánh giấu ô) | BS1: Nhập Mã ICD, nếu nhiều mã cách nhau bằng dấu phẩy | BT1: Nhập Mã ICD, nếu nhiều mã cách nhau bằng dấu phẩy | BU1: 1 - Loại 1 2 - Loại 2 3 - Loại 3 4 - Loại 4 5 - Loại 5 - Đối với Import cập nhật không cần nhập cột này | BV1: 1 - Chưa phát hiện bất thường (Có đánh giấu vào ô) 0 - Phát hiện bất thường (Không đánh giấu ô) | BW1: Nhập Mã ICD, nếu nhiều mã cách nhau bằng dấu phẩy | BX1: Nhập Mã ICD, nếu nhiều mã cách nhau bằng dấu phẩy | BY1: 1 - Loại 1 2 - Loại 2 3 - Loại 3 4 - Loại 4 5 - Loại 5 - Đối với Import cập nhật không cần nhập cột này | BZ1: 1 - Chưa phát hiện bất thường (Có đánh giấu vào ô) 0 - Phát hiện bất thường (Không đánh giấu ô) | CA1: Nhập Mã ICD, nếu nhiều mã cách nhau bằng dấu phẩy | CB1: Nhập Mã ICD, nếu nhiều mã cách nhau bằng dấu phẩy | CC1: 1 - Loại 1 2 - Loại 2 3 - Loại 3 4 - Loại 4 5 - Loại 5 - Đối với Import cập nhật không cần nhập cột này | CD1: 1 - Chưa phát hiện bất thường (Có đánh giấu vào ô) 0 - Phát hiện bất thường (Không đánh giấu ô) | CE1: Nhập Mã ICD, nếu nhiều mã cách nhau bằng dấu phẩy | CF1: Nhập Mã ICD, nếu nhiều mã cách nhau bằng dấu phẩy | CG1: 1 - Loại 1 2 - Loại 2 3 - Loại 3 4 - Loại 4 5 - Loại 5 - Đối với Import cập nhật không cần nhập cột này | CH1: 1 - Chưa phát hiện bất thường (Có đánh giấu vào ô) 0 - Phát hiện bất thường (Không đánh giấu ô) | CI1: Nhập Mã ICD, nếu nhiều mã cách nhau bằng dấu phẩy | CJ1: Nhập Mã ICD, nếu nhiều mã cách nhau bằng dấu phẩy | CK1: 1 - Loại 1 2 - Loại 2 3 - Loại 3 4 - Loại 4 5 - Loại 5 - Đối với Import cập nhật không cần nhập cột này | CL1: 1 - Chưa phát hiện bất thường (Có đánh giấu vào ô) 0 - Phát hiện bất thường (Không đánh giấu ô) | CM1: Nhập Mã ICD, nếu nhiều mã cách nhau bằng dấu phẩy | CN1: Nhập Mã ICD, nếu nhiều mã cách nhau bằng dấu phẩy | CO1: 1 - Loại 1 2 - Loại 2 3 - Loại 3 4 - Loại 4 5 - Loại 5 - Đối với Import cập nhật không cần nhập cột này | CP1: 1 - Chưa phát hiện bất thường (Có đánh giấu vào ô) 0 - Phát hiện bất thường (Không đánh giấu ô) | CQ1: Nhập Mã ICD, nếu nhiều mã cách nhau bằng dấu phẩy | CR1: Nhập Mã ICD, nếu nhiều mã cách nhau bằng dấu phẩy | CS1: 1 - Loại 1 2 - Loại 2 3 - Loại 3 4 - Loại 4 5 - Loại 5 - Đối với Import cập nhật không cần nhập cột này | CT1: 1 - Chưa phát hiện bất thường (Có đánh giấu vào ô) 0 - Phát hiện bất thường (Không đánh giấu ô) | CU1: Nhập Mã ICD, nếu nhiều mã cách nhau bằng dấu phẩy | CV1: Nhập Mã ICD, nếu nhiều mã cách nhau bằng dấu phẩy | CW1: 1 - Loại 1 2 - Loại 2 3 - Loại 3 4 - Loại 4 5 - Loại 5 - Đối với Import cập nhật không cần nhập cột này | CX1: 1 - Từ Chối Khám 0 - Không Từ Chối Khám | CY1: 1 - Chưa phát hiện bất thường (Có đánh giấu vào ô) 0 - Phát hiện bất thường (Không đánh giấu ô) | CZ1: Nhập Mã ICD, nếu nhiều mã cách nhau bằng dấu phẩy | DA1: Nhập Mã ICD, nếu nhiều mã cách nhau bằng dấu phẩy | DB1: 1 - Loại 1 2 - Loại 2 3 - Loại 3 4 - Loại 4 5 - Loại 5 | DC1: 1 - Từ Chối Khám 0 - Không Từ Chối Khám | DD1: 1 - Chưa phát hiện bất thường (Có đánh giấu vào ô) 0 - Phát hiện bất thường (Không đánh giấu ô) | DE1: Nhập Mã ICD, nếu nhiều mã cách nhau bằng dấu phẩy | DF1: Nhập Mã ICD, nếu nhiều mã cách nhau bằng dấu phẩy | DG1: 1 - Loại 1 2 - Loại 2 3 - Loại 3 4 - Loại 4 5 - Loại 5 | DH1: 1 - Chưa phát hiện bất thường (Có đánh giấu vào ô) 0 - Phát hiện bất thường (Không đánh giấu ô) | DI1: Nhập Mã ICD, nếu nhiều mã cách nhau bằng dấu phẩy | DJ1: Nhập Mã ICD, nếu nhiều mã cách nhau bằng dấu phẩy | DK1: 1 - Loại 1 2 - Loại 2 3 - Loại 3 4 - Loại 4 5 - Loại 5 - Đối với Import cập nhật không cần nhập cột này | DL1: 1 - Chưa phát hiện bất thường (Có đánh giấu vào ô) 0 - Phát hiện bất thường (Không đánh giấu ô) | DM1: Nhập Mã ICD, nếu nhiều mã cách nhau bằng dấu phẩy | DN1: Nhập Mã ICD, nếu nhiều mã cách nhau bằng dấu phẩy | DO1: 1 - Loại 1 2 - Loại 2 3 - Loại 3 4 - Loại 4 5 - Loại 5 - Đối với Import cập nhật không cần nhập cột này | DP1: 1 - Chưa phát hiện bất thường (Có đánh giấu vào ô) 0 - Phát hiện bất thường (Không đánh giấu ô) | DQ1: Nhập Mã ICD, nếu nhiều mã cách nhau bằng dấu phẩy | DR1: Nhập Mã ICD, nếu nhiều mã cách nhau bằng dấu phẩy | DS1: 1 - Loại 1 2 - Loại 2 3 - Loại 3 4 - Loại 4 5 - Loại 5 - Đối với Import cập nhật không cần nhập cột này | DT1: Nhập thông tin khám chuyên khoa mắt | EJ1: Thông tin khám 1 - Khám Tuyển 2 - Khám Định kỳ -Đối với import cập nhật khpong cần nhập cột này | EK1: Nhập giá trị số | FG1: Nhập số hoặc negative | FI1: 0 - Dương Tính 1 - Âm Tính Nhập số | FJ1: Nhập số hoặc negative | FO1: Nhập tự do | FQ1: 1 - Có 2 - Không Nhập số | FR1: Nhập tự do | FS1: Riêng đối với nữ lao động - Nhập tự do | FW1: Chọn danh mục trong ô nhập liệu - Đối vơi simport cập nhật không cần nhập ô này | FX1: Nhập khi chọn Đề nghị (Chuyển tuyến, khám chuyên khoa) | FY1: Nhập tự do
A2: STT | B2: Mã phiếu | C2: Ngày khám* | D2: Đối tượng khám* | E2: Địa điểm khám* | F2: Số CMND/CCCD* | G2: Họ và tên* | H2: Ngày sinh* | I2: Giới tính* | J2: Dân tộc | K2: Nhóm máu | L2: Yếu tố nhóm máu | M2: Bảo hiểm y tế | N2: SĐT* | O2: Chỗ ở hiện tại* | P2: Tỉnh * | Q2: Phường xã* | R2: Nghề Nghiệp | S2: Nơi làm việc/Công Tác | T2: Nơi công tác Tỉnh | U2: Nơi công tác xã phường | V2: Lý do khám sức khỏe | W2: Tình trạng thực hiện xét nghiệm * | X2: Hình thức chi trả khám sức khỏe* | Y2: Hình thức khám * | Z2: Nguồn khác (nếu có) | AA2: Trong gia đình, ông, bà, bố, mẹ, anh, chị em ruột có mắc các bệnh dưới đây không | AB2: Khác | AC2: Có bệnh hay bị thương trong 5 năm qua * | AD2: Có bệnh thần kinh hay bị thương ở đầu * | AE2: Bệnh mắt hoặc giảm thị lực (trừ trường hợp đeo kính thuốc) * | AF2: Bệnh ở tai, giảm sức nghe hoặc thăng bằng * | AG2: Bệnh ở tim, hoặc nhồi máu cơ tim, các bệnh tim mạch khác * | AH2: Phẫu thuật can thiệp tim - mạch (thay van, bắc cầu nối, tạo hình mạch, máy tạo nhịp, đặt stent mạch, ghép tim) * | AI2: Tăng huyết áp * | AJ2: Khó thở * | AK2: Bệnh phổi, hen, khí phế thũng, viêm phế quản mạn tính * | AL2: Bệnh thận, lọc máu * | AM2: Nghiện rượu, bia * | AN2: Đái tháo đường hoặc kiểm soát tăng đường huyết * | AO2: Bệnh tâm thần * | AP2: Mất ý thức, rối loạn ý thức * | AQ2: Ngất, chóng mặt * | AR2: Bệnh tiêu hóa * | AS2: Rối loạn giấc ngủ, ngừng thở khi ngủ, ngủ rũ ban ngày, ngáy to * | AT2: Tai biến mạch máu não hoặc liệt * | AU2: Bệnh hoặc tổn thương cột sống * | AV2: Sử dụng rượu, bia thường xuyên, liên tục * | AW2: Sử dụng ma túy và chất gây nghiện * | AX2: Bệnh khác (ghi rõ) | AY2: Ông (bà) có đang điều trị bệnh gì không? | AZ2: Nếu có | BA2: Tiền sử thai sản | BB2: Nếu có | BC2: Chiều Cao * | BD2: Cân nặng * | BE2: Nhịp Thở * | BF2: Mạch * | BG2: Huyết áp TT * | BH2: Huyết áp TTr * | BI2: Phân Loại thể lực * | BJ2: Tuần Hoàn | BN2: Hô Hấp | BR2: Tiêu Hóa | BV2: Thận - Tiết Niệu | BZ2: Nội Tiết | CD2: Cơ Xương Khớp | CH2: Thần Kinh | CL2: Tâm Thần | CP2: Ngoại Khoa | CT2: Da Liễu | CX2: Sản Khoa | DC2: Phụ Khoa | DH2: Mắt | DL2: Tai Mũi Họng | DP2: Răng Hàm Mặt | DT2: Khám thị lực | DZ2: Khám khúc xạ(Nếu có) | EF2: Kết quả khám thính lực | EJ2: Loại khám * | EK2: Số lượng HC (T/L) | EL2: Huyết sắc tố (g/L) | EM2: Hematocrit L/L) | EN2: MCV (fL) | EO2: MCH (pg) | EP2: MCHC (g/L) | EQ2: RDW (%) | ER2: Số lượng bạch cầu (G/L) | ES2: Số lượng bạch cầu trung tính (G/L) | ET2: Số lượng bạch cầu lympho (G/L) | EU2: Số lượng bạch cầu đơn nhân (G/L) | EV2: Số lượng bạch cầu ái toan (G/L) | EW2: Số lượng bạch cầu ái kiềm (G/L) | EX2: Số lượng tiểu cầu (G/L) | EY2: Đường máu (mmol/L) | EZ2: Đường máu lúc đói (mmol/L) | FA2: Urê (mmol/L) | FB2: Creatinin (umol/L) | FC2: ASAT(GOT) (U/L) | FD2: ALAT (GPT) (U/L) | FE2: Tỉ trọng | FF2: pH | FG2: Bạch cầu (Leu/uL) | FH2: Hồng cầu (Ery/uL) | FI2: Nitrit (neg/pos) | FJ2: Protein (g/L) | FK2: Glucose (mmol/L) | FL2: Thể cetonic (mmol/L) | FM2: Bilirubin (umol/L) | FN2: Urobilinogen (umol/L) | FO2: Khác (nếu có) | FP2: Kết quả Chẩn đoán hình ảnh (XQuang tim phổi thẳng) | FQ2: Cận lâm sàng khác | FR2: Nếu có, liệt kê kết quả chi tiết | FS2: XN Cổ tử cung | FT2: Xét nghiệm HPV (nếu có) | FU2: X-Quang nhũ (nếu có) | FV2: Siêu âm 02 tuyến vú (nếu có) | FW2: Kết Luận
BJ3: Chưa phát hiện bất thường | BK3: Chẩn Đoán Sơ Bộ | BL3: Chẩn Đoán Xác Định | BM3: Phân loại * | BN3: Chưa phát hiện bất thường | BO3: Chẩn Đoán Sơ Bộ | BP3: Chẩn Đoán Xác Định | BQ3: Phân loại * | BR3: Chưa phát hiện bất thường | BS3: Chẩn Đoán Sơ Bộ | BT3: Chẩn Đoán Xác Định | BU3: Phân loại * | BV3: Chưa phát hiện bất thường | BW3: Chẩn Đoán Sơ Bộ | BX3: Chẩn Đoán Xác Định | BY3: Phân loại * | BZ3: Chưa phát hiện bất thường | CA3: Chẩn Đoán Sơ Bộ | CB3: Chẩn Đoán Xác Định | CC3: Phân loại * | CD3: Chưa phát hiện bất thường | CE3: Chẩn Đoán Sơ Bộ | CF3: Chẩn Đoán Xác Định | CG3: Phân loại * | CH3: Chưa phát hiện bất thường | CI3: Chẩn Đoán Sơ Bộ | CJ3: Chẩn Đoán Xác Định | CK3: Phân loại * | CL3: Chưa phát hiện bất thường | CM3: Chẩn Đoán Sơ Bộ | CN3: Chẩn Đoán Xác Định | CO3: Phân loại * | CP3: Chưa phát hiện bất thường | CQ3: Chẩn Đoán Sơ Bộ | CR3: Chẩn Đoán Xác Định | CS3: Phân loại * | CT3: Chưa phát hiện bất thường | CU3: Chẩn Đoán Sơ Bộ | CV3: Chẩn Đoán Xác Định | CW3: Phân loại * | CX3: Từ Chối Khám | CY3: Chưa phát hiện bất thường | CZ3: Chẩn Đoán Sơ Bộ | DA3: Chẩn Đoán Xác Định | DB3: Phân loại | DC3: Từ Chối Khám | DD3: Chưa phát hiện bất thường | DE3: Chẩn Đoán Sơ Bộ | DF3: Chẩn Đoán Xác Định | DG3: Phân loại | DH3: Chưa phát hiện bất thường | DI3: Chẩn Đoán Sơ Bộ | DJ3: Chẩn Đoán Xác Định | DK3: Phân loại * | DL3: Chưa phát hiện bất thường | DM3: Chẩn Đoán Sơ Bộ | DN3: Chẩn Đoán Xác Định | DO3: Phân loại * | DP3: Chưa phát hiện bất thường | DQ3: Chẩn Đoán Sơ Bộ | DR3: Chẩn Đoán Xác Định | DS3: Phân loại * | DT3: Không Kính (MP) | DU3: Không Kính (MT) | DV3: Kính Lỗ (MP) | DW3: Kính Lỗ (MT) | DX3: Có Kính (MP) | DY3: Có Kính (MT) | DZ3: MP(Độ Cầu) | EA3: MP(Độ Trụ) | EB3: MP(Trục) | EC3: MT(Độ Cầu) | ED3: MT(Độ Trụ) | EE3: MT(Trục) | EF3: Tai trái (Nói thường) | EG3: Tai phải (Nói Thường) | EH3: Tai trái (Nói thầm) | EI3: Tai phải (Nói thầm) | FW3: Đề Nghị * | FX3: Đề nghị chuyển tuyến (Ghi rõ) | FY3: Ghi rõ | GI3: Nơi công tác tỉnh
B4: ma_phieu | C4: ngay_kham | D4: doi_tuong_kham | E4: dia_diem_kham | F4: dinh_danh_ca_nhan | G4: ho_ten | H4: ngay_sinh | I4: gioi_tinh | J4: dan_toc_id | K4: nhom_mau_id | L4: yeu_to_nhom_mau_id | M4: the_bhyt | N4: sdt | O4: dia_chi_hien_tai | P4: city_id | Q4: ward_id | R4: nghenghiep_code | S4: noi_cong_tac_id | U4: noi_cong_tac_xa_phuong | V4: ly_do_kham | W4: tinhtrangthucnghiem_xetnghiem | X4: hinh_thuc_chi_tra_khamsk | Y4: hinh_thuc_chi_tra_khamsk_chi_tiet | Z4: nguonkhac_ghiro | AA4: giadinh_macbenh | AB4: giadinh_danhsachbenh_icd | AC4: benh_5nam | AD4: benh_than_kinh | AE4: benh_mat | AF4: benh_tai | AG4: benh_tim | AH4: pt_tim_mach | AI4: tang_ha | AJ4: kho_tho | AK4: benh_phoi | AL4: benh_than | AM4: nghien_ruou_bia | AN4: dai_thao_duong | AO4: benh_tam_than | AP4: mat_y_thuc | AQ4: ngat_chong_mat | AR4: benh_tieu_hoa | AS4: roi_loan_giac_ngu | AT4: tai_bien_mach_mau_nao | AU4: cot_song | AV4: su_dung_ruou_bia | AW4: su_dung_ma_tuy | AX4: benh_khac | AY4: dieu_tri_benh_co_khong | AZ4: dieu_tri_benh_liet_ke | BA4: thai_san_co_khong | BB4: thai_san_liet_ke | BC4: chieucao | BD4: cannang | BE4: nhiptho | BF4: mach | BG4: huyetaptamthu | BH4: huyetaptamtruong | BI4: phanloai | BJ4: noikhoa_chuaphathienbatthuong | BK4: noikhoa_chandoansobo_icd | BL4: noikhoa_chandoanxacdinh_icd | BM4: noikhoa_phanloai | BN4: hohap_chuaphathienbatthuong | BO4: hohap_chandoansobo_icd | BP4: hohap_chandoanxacdinh_icd | BQ4: hohap_phanloai | BR4: tieuhoa_chuaphathienbatthuong | BS4: tieuhoa_chandoansobo_icd | BT4: tieuhoa_chandoanxacdinh_icd | BU4: tieuhoa_phanloai | BV4: thantietnieu_chuaphathienbatthuong | BW4: thantietnieu_chandoansobo_icd | BX4: thantietnieu_chandoanxacdinh_icd | BY4: thantietnieu_phanloai | BZ4: noitiet_chuaphathienbatthuong | CA4: noitiet_chandoansobo_icd | CB4: noitiet_chandoanxacdinh_icd | CC4: noitiet_phanloai | CD4: coxuongkhop_chuaphathienbatthuong | CE4: coxuongkhop_chandoansobo_icd | CF4: coxuongkhop_chandoanxacdinh_icd | CG4: coxuongkhop_phanloai | CH4: thankinh_chuaphathienbatthuong | CI4: thankinh_chuandoansobo_icd | CJ4: thankinh_chandoanxacdinh_icd | CK4: thankinh_phanloai | CL4: tamthan_chuaphathienbatthuong | CM4: tamthan_chandoansobo_icd | CN4: tamthan_chandoanxacdinh_icd | CO4: tamthan_phanloai | CP4: ngoaikhoa_chuaphathienbatthuong | CQ4: ngoaikhoa_chandoansobo_icd | CR4: ngoaikhoa_chandoanxacdinh_icd | CS4: ngoaikhoa_phanloai | CT4: dalieu_chuaphathienbatthuong | CU4: dalieu_chandoansobo_icd | CV4: dalieu_chandoanxacdinh_icd | CW4: dalieu_phanloai | CX4: sankhoa_tuchoikham | CY4: sankhoa_chuaphathienbatthuong | CZ4: sankhoa_chandoansobo_icd | DA4: sankhoa_chandoanxacdinh_icd | DB4: sankhoa_phanloai | DC4: phukhoa_tuchoikham | DD4: phukhoa_chuaphathienbatthuong | DE4: phukhoa_chandoansobo_icd | DF4: phukhoa_chandoanxacdinh_icd | DG4: phukhoa_phanloai | DH4: mat_chuaphathienbatthuong | DI4: mat_chandoansobo_icd | DJ4: mat_chandoanxacdinh_icd | DK4: mat_phanloai | DL4: tmh_chuaphathienbatthuong | DM4: tmh_chandoansobo_icd | DN4: tmh_chandoanxacdinh_icd | DO4: tmh_phanloai | DP4: rhm_chuaphathienbatthuong | DQ4: rhm_chandoansobo_icd | DR4: rhm_chandoanxacdinh_icd | DS4: rhm_phanloai | DT4: mat_khongkinh_mp | DU4: mat_khongkinh_mt | DV4: mat_kinhlo_mp | DW4: mat_kinhlo_mt | DX4: mat_cokinh_mp | DY4: mat_cokinh_mt | DZ4: mat_docau_mp | EA4: mat_dotru_mp | EB4: mat_truc_mp | EC4: mat_docau_mt | ED4: mat_dotru_mt | EE4: mat_truc_mt | EF4: tai_noithuong_tt | EG4: tai_noithuong_tp | EH4: tai_noitham_tt | EI4: tai_noitham_tp | EJ4: loai_kham | EK4: kskdk_xnm_slhc | EL4: kskdk_xnm_huyetsacto | EM4: kskdk_xnm_hematocrit | EN4: kskdk_xnm_mcv | EO4: kskdk_xnm_mch | EP4: kskdk_xnm_mchc | EQ4: kskdk_xnm_rdw | ER4: kskdk_xnm_slbc | ES4: kskdk_xnm_slbc_trungtinh | ET4: kskdk_xnm_slbc_lympho | EU4: kskdk_xnm_slbc_donnhan | EV4: kskdk_xnm_slbc_aitoan | EW4: kskdk_xnm_slbc_aikiem | EX4: kskdk_xnm_sltc | EY4: kskdk_shm_duongmau | EZ4: kskdk_shm_duongmau_lucdoi | FA4: kskdk_shm_ure | FB4: kskdk_shm_creatinin | FC4: kskdk_shm_asat_got | FD4: kskdk_shm_alat_gpt | FE4: kskdk_xnnt_titrong | FF4: kskdk_xnnt_ph | FG4: kskdk_xnnt_bachcau | FH4: kskdk_xnnt_hongcau | FI4: kskdk_xnnt_nitrit | FJ4: kskdk_xnnt_protein | FK4: kskdk_xnnt_glucose | FL4: kskdk_xnnt_cetonic | FM4: kskdk_xnnt_bilirubin | FN4: kskdk_xnnt_urobilinogen | FO4: kskdk_xnnt_khac | FP4: kskdk_chuan_doan_hinh_anh | FQ4: can_lam_sang_khac | FR4: can_lam_sang_khac_chi_tiet | FS4: xet_nghiem_te_bao_co_tu_cung | FT4: xet_nghiem_hpv | FU4: xquang_nhu | FV4: sieu_am_2_tuyen_vu | FW4: danh_muc_de_nghi | FX4: denghi_chuyentuyen_ghiro | FY4: de_nghi | GE4: nghenghiep_id | GF4: noi_cong_tac
GE5: =IFERROR(VLOOKUP(R5,NgheNghiep!$A$2:$B$1074,2,FALSE),"") | GF5: {=IFERROR(INDEX(NoiLamViec_Table[Nơi làm việc],MATCH(S5,NoiLamViec_Table[Mã],0)),"")} | GG5: =IFERROR(VLOOKUP(P5,Tinh!$A$2:$C$35,2,FALSE),"") | GH5: {=IFERROR(_xlfn.XLOOKUP(1, (WARD[CityId] = GG5) * (WARD[WardName] = Q5), WARD[WardId]), "")} | GI5: =IFERROR(VLOOKUP(T5,Tinh!$A$2:$C$35,2,FALSE),"")
GE6: =IFERROR(VLOOKUP(R6,NgheNghiep!$A$2:$B$1074,2,FALSE),"") | GF6: {=IFERROR(INDEX(NoiLamViec_Table[Nơi làm việc],MATCH(S6,NoiLamViec_Table[Mã],0)),"")} | GG6: =IFERROR(VLOOKUP(P6,Tinh!$A$2:$C$35,2,FALSE),"") | GH6: {=IFERROR(_xlfn.XLOOKUP(1, (WARD[CityId] = GG6) * (WARD[WardName] = Q6), WARD[WardId]), "")} | GI6: =IFERROR(VLOOKUP(T6,Tinh!$A$2:$C$35,2,FALSE),"")
GE7: =IFERROR(VLOOKUP(R7,NgheNghiep!$A$2:$B$1074,2,FALSE),"") | GF7: {=IFERROR(INDEX(NoiLamViec_Table[Nơi làm việc],MATCH(S7,NoiLamViec_Table[Mã],0)),"")} | GG7: =IFERROR(VLOOKUP(P7,Tinh!$A$2:$C$35,2,FALSE),"") | GH7: {=IFERROR(_xlfn.XLOOKUP(1, (WARD[CityId] = GG7) * (WARD[WardName] = Q7), WARD[WardId]), "")} | GI7: =IFERROR(VLOOKUP(T7,Tinh!$A$2:$C$35,2,FALSE),"")
GE8: =IFERROR(VLOOKUP(R8,NgheNghiep!$A$2:$B$1074,2,FALSE),"") | GF8: {=IFERROR(INDEX(NoiLamViec_Table[Nơi làm việc],MATCH(S8,NoiLamViec_Table[Mã],0)),"")} | GG8: =IFERROR(VLOOKUP(P8,Tinh!$A$2:$C$35,2,FALSE),"") | GH8: {=IFERROR(_xlfn.XLOOKUP(1, (WARD[CityId] = GG8) * (WARD[WardName] = Q8), WARD[WardId]), "")} | GI8: =IFERROR(VLOOKUP(T8,Tinh!$A$2:$C$35,2,FALSE),"")
GE9: =IFERROR(VLOOKUP(R9,NgheNghiep!$A$2:$B$1074,2,FALSE),"") | GF9: {=IFERROR(INDEX(NoiLamViec_Table[Nơi làm việc],MATCH(S9,NoiLamViec_Table[Mã],0)),"")} | GG9: =IFERROR(VLOOKUP(P9,Tinh!$A$2:$C$35,2,FALSE),"") | GH9: {=IFERROR(_xlfn.XLOOKUP(1, (WARD[CityId] = GG9) * (WARD[WardName] = Q9), WARD[WardId]), "")} | GI9: =IFERROR(VLOOKUP(T9,Tinh!$A$2:$C$35,2,FALSE),"")
GE10: =IFERROR(VLOOKUP(R10,NgheNghiep!$A$2:$B$1074,2,FALSE),"") | GF10: {=IFERROR(INDEX(NoiLamViec_Table[Nơi làm việc],MATCH(#REF!,NoiLamViec_Table[Mã],0)),"")} | GG10: =IFERROR(VLOOKUP(P10,Tinh!$A$2:$C$35,2,FALSE),"") | GH10: {=IFERROR(_xlfn.XLOOKUP(1, (WARD[CityId] = GG10) * (WARD[WardName] = Q10), WARD[WardId]), "")} | GI10: =IFERROR(VLOOKUP(T10,Tinh!$A$2:$C$35,2,FALSE),"")
GE11: =IFERROR(VLOOKUP(R11,NgheNghiep!$A$2:$B$1074,2,FALSE),"") | GF11: {=IFERROR(INDEX(NoiLamViec_Table[Nơi làm việc],MATCH(S10,NoiLamViec_Table[Mã],0)),"")} | GG11: =IFERROR(VLOOKUP(P11,Tinh!$A$2:$C$35,2,FALSE),"") | GH11: {=IFERROR(_xlfn.XLOOKUP(1, (WARD[CityId] = GG11) * (WARD[WardName] = Q11), WARD[WardId]), "")} | GI11: =IFERROR(VLOOKUP(T11,Tinh!$A$2:$C$35,2,FALSE),"")
GE12: =IFERROR(VLOOKUP(R12,NgheNghiep!$A$2:$B$1074,2,FALSE),"") | GF12: {=IFERROR(INDEX(NoiLamViec_Table[Nơi làm việc],MATCH(S12,NoiLamViec_Table[Mã],0)),"")} | GG12: =IFERROR(VLOOKUP(P12,Tinh!$A$2:$C$35,2,FALSE),"") | GH12: {=IFERROR(_xlfn.XLOOKUP(1, (WARD[CityId] = GG12) * (WARD[WardName] = Q12), WARD[WardId]), "")} | GI12: =IFERROR(VLOOKUP(T12,Tinh!$A$2:$C$35,2,FALSE),"")
GE13: =IFERROR(VLOOKUP(R13,NgheNghiep!$A$2:$B$1074,2,FALSE),"") | GF13: {=IFERROR(INDEX(NoiLamViec_Table[Nơi làm việc],MATCH(S13,NoiLamViec_Table[Mã],0)),"")} | GG13: =IFERROR(VLOOKUP(P13,Tinh!$A$2:$C$35,2,FALSE),"") | GH13: {=IFERROR(_xlfn.XLOOKUP(1, (WARD[CityId] = GG13) * (WARD[WardName] = Q13), WARD[WardId]), "")} | GI13: =IFERROR(VLOOKUP(T13,Tinh!$A$2:$C$35,2,FALSE),"")
GE14: =IFERROR(VLOOKUP(R14,NgheNghiep!$A$2:$B$1074,2,FALSE),"") | GF14: {=IFERROR(INDEX(NoiLamViec_Table[Nơi làm việc],MATCH(S14,NoiLamViec_Table[Mã],0)),"")} | GG14: =IFERROR(VLOOKUP(P14,Tinh!$A$2:$C$35,2,FALSE),"") | GH14: {=IFERROR(_xlfn.XLOOKUP(1, (WARD[CityId] = GG14) * (WARD[WardName] = Q14), WARD[WardId]), "")} | GI14: =IFERROR(VLOOKUP(T14,Tinh!$A$2:$C$35,2,FALSE),"")
GE15: =IFERROR(VLOOKUP(R15,NgheNghiep!$A$2:$B$1074,2,FALSE),"") | GF15: {=IFERROR(INDEX(NoiLamViec_Table[Nơi làm việc],MATCH(S15,NoiLamViec_Table[Mã],0)),"")} | GG15: =IFERROR(VLOOKUP(P15,Tinh!$A$2:$C$35,2,FALSE),"") | GH15: {=IFERROR(_xlfn.XLOOKUP(1, (WARD[CityId] = GG15) * (WARD[WardName] = Q15), WARD[WardId]), "")} | GI15: =IFERROR(VLOOKUP(T15,Tinh!$A$2:$C$35,2,FALSE),"")
GE16: =IFERROR(VLOOKUP(R16,NgheNghiep!$A$2:$B$1074,2,FALSE),"") | GF16: {=IFERROR(INDEX(NoiLamViec_Table[Nơi làm việc],MATCH(S16,NoiLamViec_Table[Mã],0)),"")} | GG16: =IFERROR(VLOOKUP(P16,Tinh!$A$2:$C$35,2,FALSE),"") | GH16: {=IFERROR(_xlfn.XLOOKUP(1, (WARD[CityId] = GG16) * (WARD[WardName] = Q16), WARD[WardId]), "")} | GI16: =IFERROR(VLOOKUP(T16,Tinh!$A$2:$C$35,2,FALSE),"")
GE17: =IFERROR(VLOOKUP(R17,NgheNghiep!$A$2:$B$1074,2,FALSE),"") | GF17: {=IFERROR(INDEX(NoiLamViec_Table[Nơi làm việc],MATCH(S17,NoiLamViec_Table[Mã],0)),"")} | GG17: =IFERROR(VLOOKUP(P17,Tinh!$A$2:$C$35,2,FALSE),"") | GH17: {=IFERROR(_xlfn.XLOOKUP(1, (WARD[CityId] = GG17) * (WARD[WardName] = Q17), WARD[WardId]), "")} | GI17: =IFERROR(VLOOKUP(T17,Tinh!$A$2:$C$35,2,FALSE),"")
GE18: =IFERROR(VLOOKUP(R18,NgheNghiep!$A$2:$B$1074,2,FALSE),"") | GF18: {=IFERROR(INDEX(NoiLamViec_Table[Nơi làm việc],MATCH(S18,NoiLamViec_Table[Mã],0)),"")} | GG18: =IFERROR(VLOOKUP(P18,Tinh!$A$2:$C$35,2,FALSE),"") | GH18: {=IFERROR(_xlfn.XLOOKUP(1, (WARD[CityId] = GG18) * (WARD[WardName] = Q18), WARD[WardId]), "")} | GI18: =IFERROR(VLOOKUP(T18,Tinh!$A$2:$C$35,2,FALSE),"")
GE19: =IFERROR(VLOOKUP(R19,NgheNghiep!$A$2:$B$1074,2,FALSE),"") | GF19: {=IFERROR(INDEX(NoiLamViec_Table[Nơi làm việc],MATCH(S19,NoiLamViec_Table[Mã],0)),"")} | GG19: =IFERROR(VLOOKUP(P19,Tinh!$A$2:$C$35,2,FALSE),"") | GH19: {=IFERROR(_xlfn.XLOOKUP(1, (WARD[CityId] = GG19) * (WARD[WardName] = Q19), WARD[WardId]), "")} | GI19: =IFERROR(VLOOKUP(T19,Tinh!$A$2:$C$35,2,FALSE),"")
GE20: =IFERROR(VLOOKUP(R20,NgheNghiep!$A$2:$B$1074,2,FALSE),"") | GF20: {=IFERROR(INDEX(NoiLamViec_Table[Nơi làm việc],MATCH(S20,NoiLamViec_Table[Mã],0)),"")} | GG20: =IFERROR(VLOOKUP(P20,Tinh!$A$2:$C$35,2,FALSE),"") | GH20: {=IFERROR(_xlfn.XLOOKUP(1, (WARD[CityId] = GG20) * (WARD[WardName] = Q20), WARD[WardId]), "")} | GI20: =IFERROR(VLOOKUP(T20,Tinh!$A$2:$C$35,2,FALSE),"")
GE21: =IFERROR(VLOOKUP(R21,NgheNghiep!$A$2:$B$1074,2,FALSE),"") | GF21: {=IFERROR(INDEX(NoiLamViec_Table[Nơi làm việc],MATCH(S21,NoiLamViec_Table[Mã],0)),"")} | GG21: =IFERROR(VLOOKUP(P21,Tinh!$A$2:$C$35,2,FALSE),"") | GH21: {=IFERROR(_xlfn.XLOOKUP(1, (WARD[CityId] = GG21) * (WARD[WardName] = Q21), WARD[WardId]), "")} | GI21: =IFERROR(VLOOKUP(T21,Tinh!$A$2:$C$35,2,FALSE),"")
GE22: =IFERROR(VLOOKUP(R22,NgheNghiep!$A$2:$B$1074,2,FALSE),"") | GF22: {=IFERROR(INDEX(NoiLamViec_Table[Nơi làm việc],MATCH(S22,NoiLamViec_Table[Mã],0)),"")} | GG22: =IFERROR(VLOOKUP(P22,Tinh!$A$2:$C$35,2,FALSE),"") | GH22: {=IFERROR(_xlfn.XLOOKUP(1, (WARD[CityId] = GG22) * (WARD[WardName] = Q22), WARD[WardId]), "")} | GI22: =IFERROR(VLOOKUP(T22,Tinh!$A$2:$C$35,2,FALSE),"")
GE23: =IFERROR(VLOOKUP(R23,NgheNghiep!$A$2:$B$1074,2,FALSE),"") | GF23: {=IFERROR(INDEX(NoiLamViec_Table[Nơi làm việc],MATCH(S23,NoiLamViec_Table[Mã],0)),"")} | GG23: =IFERROR(VLOOKUP(P23,Tinh!$A$2:$C$35,2,FALSE),"") | GH23: {=IFERROR(_xlfn.XLOOKUP(1, (WARD[CityId] = GG23) * (WARD[WardName] = Q23), WARD[WardId]), "")} | GI23: =IFERROR(VLOOKUP(T23,Tinh!$A$2:$C$35,2,FALSE),"")
... GE1040: =IFERROR(VLOOKUP(R1040,NgheNghiep!$A$2:$B$1074,2,FALSE),"") | GF1040: {=IFERROR(INDEX(NoiLamViec_Table[Nơi làm việc],MATCH(S1040,NoiLamViec_Table[Mã],0)),"")} | GG1040: =IFERROR(VLOOKUP(P1040,Tinh!$A$2:$C$35,2,FALSE),"") | GH1040: {=IFERROR(_xlfn.XLOOKUP(1, (WARD[CityId] = GG1040) * (WARD[WardName] = Q1040), WARD[WardId]), "")} | GI1040: =IFERROR(VLOOKUP(T1040,Tinh!$A$2:$C$35,2,FALSE),"")
GE1041: =IFERROR(VLOOKUP(R1041,NgheNghiep!$A$2:$B$1074,2,FALSE),"") | GF1041: {=IFERROR(INDEX(NoiLamViec_Table[Nơi làm việc],MATCH(S1041,NoiLamViec_Table[Mã],0)),"")} | GH1041: {=IFERROR(_xlfn.XLOOKUP(1, (WARD[CityId] = GG1041) * (WARD[WardName] = Q1041), WARD[WardId]), "")}
GE1042: =IFERROR(VLOOKUP(R1042,NgheNghiep!$A$2:$B$1074,2,FALSE),"") | GF1042: {=IFERROR(INDEX(NoiLamViec_Table[Nơi làm việc],MATCH(S1042,NoiLamViec_Table[Mã],0)),"")} | GH1042: {=IFERROR(_xlfn.XLOOKUP(1, (WARD[CityId] = GG1042) * (WARD[WardName] = Q1042), WARD[WardId]), "")}
GE1043: =IFERROR(VLOOKUP(R1043,NgheNghiep!$A$2:$B$1074,2,FALSE),"") | GF1043: {=IFERROR(INDEX(NoiLamViec_Table[Nơi làm việc],MATCH(S1043,NoiLamViec_Table[Mã],0)),"")} | GH1043: {=IFERROR(_xlfn.XLOOKUP(1, (WARD[CityId] = GG1043) * (WARD[WardName] = Q1043), WARD[WardId]), "")}
GE1044: =IFERROR(VLOOKUP(R1044,NgheNghiep!$A$2:$B$1074,2,FALSE),"") | GF1044: {=IFERROR(INDEX(NoiLamViec_Table[Nơi làm việc],MATCH(S1044,NoiLamViec_Table[Mã],0)),"")} | GH1044: {=IFERROR(_xlfn.XLOOKUP(1, (WARD[CityId] = GG1044) * (WARD[WardName] = Q1044), WARD[WardId]), "")}
GE1045: =IFERROR(VLOOKUP(R1045,NgheNghiep!$A$2:$B$1074,2,FALSE),"") | GF1045: {=IFERROR(INDEX(NoiLamViec_Table[Nơi làm việc],MATCH(S1045,NoiLamViec_Table[Mã],0)),"")} | GH1045: {=IFERROR(_xlfn.XLOOKUP(1, (WARD[CityId] = GG1045) * (WARD[WardName] = Q1045), WARD[WardId]), "")}
GE1046: =IFERROR(VLOOKUP(R1046,NgheNghiep!$A$2:$B$1074,2,FALSE),"") | GF1046: {=IFERROR(INDEX(NoiLamViec_Table[Nơi làm việc],MATCH(S1046,NoiLamViec_Table[Mã],0)),"")} | GH1046: {=IFERROR(_xlfn.XLOOKUP(1, (WARD[CityId] = GG1046) * (WARD[WardName] = Q1046), WARD[WardId]), "")}
GE1047: =IFERROR(VLOOKUP(R1047,NgheNghiep!$A$2:$B$1074,2,FALSE),"") | GF1047: {=IFERROR(INDEX(NoiLamViec_Table[Nơi làm việc],MATCH(S1047,NoiLamViec_Table[Mã],0)),"")} | GH1047: {=IFERROR(_xlfn.XLOOKUP(1, (WARD[CityId] = GG1047) * (WARD[WardName] = Q1047), WARD[WardId]), "")}
GE1048: =IFERROR(VLOOKUP(R1048,NgheNghiep!$A$2:$B$1074,2,FALSE),"") | GF1048: {=IFERROR(INDEX(NoiLamViec_Table[Nơi làm việc],MATCH(S1048,NoiLamViec_Table[Mã],0)),"")} | GH1048: {=IFERROR(_xlfn.XLOOKUP(1, (WARD[CityId] = GG1048) * (WARD[WardName] = Q1048), WARD[WardId]), "")}
GE1049: =IFERROR(VLOOKUP(R1049,NgheNghiep!$A$2:$B$1074,2,FALSE),"") | GF1049: {=IFERROR(INDEX(NoiLamViec_Table[Nơi làm việc],MATCH(S1049,NoiLamViec_Table[Mã],0)),"")} | GH1049: {=IFERROR(_xlfn.XLOOKUP(1, (WARD[CityId] = GG1049) * (WARD[WardName] = Q1049), WARD[WardId]), "")}
GE1050: =IFERROR(VLOOKUP(R1050,NgheNghiep!$A$2:$B$1074,2,FALSE),"") | GF1050: {=IFERROR(INDEX(NoiLamViec_Table[Nơi làm việc],MATCH(S1050,NoiLamViec_Table[Mã],0)),"")} | GH1050: {=IFERROR(_xlfn.XLOOKUP(1, (WARD[CityId] = GG1050) * (WARD[WardName] = Q1050), WARD[WardId]), "")}
GE1051: =IFERROR(VLOOKUP(R1051,NgheNghiep!$A$2:$B$1074,2,FALSE),"") | GF1051: {=IFERROR(INDEX(NoiLamViec_Table[Nơi làm việc],MATCH(S1051,NoiLamViec_Table[Mã],0)),"")} | GH1051: {=IFERROR(_xlfn.XLOOKUP(1, (WARD[CityId] = GG1051) * (WARD[WardName] = Q1051), WARD[WardId]), "")}
GE1052: =IFERROR(VLOOKUP(R1052,NgheNghiep!$A$2:$B$1074,2,FALSE),"") | GF1052: {=IFERROR(INDEX(NoiLamViec_Table[Nơi làm việc],MATCH(S1052,NoiLamViec_Table[Mã],0)),"")} | GH1052: {=IFERROR(_xlfn.XLOOKUP(1, (WARD[CityId] = GG1052) * (WARD[WardName] = Q1052), WARD[WardId]), "")}
... GE1125: =IFERROR(VLOOKUP(R1125,NgheNghiep!$A$2:$B$1074,2,FALSE),"") | GF1125: {=IFERROR(INDEX(NoiLamViec_Table[Nơi làm việc],MATCH(S1125,NoiLamViec_Table[Mã],0)),"")} | GH1125: {=IFERROR(_xlfn.XLOOKUP(1, (WARD[CityId] = GG1125) * (WARD[WardName] = Q1125), WARD[WardId]), "")}
GF1126: {=IFERROR(INDEX(NoiLamViec_Table[Nơi làm việc],MATCH(S1126,NoiLamViec_Table[Mã],0)),"")} | GH1126: {=IFERROR(_xlfn.XLOOKUP(1, (WARD[CityId] = GG1126) * (WARD[WardName] = Q1126), WARD[WardId]), "")}
GF1127: {=IFERROR(INDEX(NoiLamViec_Table[Nơi làm việc],MATCH(S1127,NoiLamViec_Table[Mã],0)),"")} | GH1127: {=IFERROR(_xlfn.XLOOKUP(1, (WARD[CityId] = GG1127) * (WARD[WardName] = Q1127), WARD[WardId]), "")}
GF1128: {=IFERROR(INDEX(NoiLamViec_Table[Nơi làm việc],MATCH(S1128,NoiLamViec_Table[Mã],0)),"")} | GH1128: {=IFERROR(_xlfn.XLOOKUP(1, (WARD[CityId] = GG1128) * (WARD[WardName] = Q1128), WARD[WardId]), "")}
...

Sheet TienSuGiaDinh
A1: ID | B1: Bệnh Tiền Sử Gia Đình
A2: 1051 | B2: Truyền nhiễm
A3: 1052 | B3: Tim mạch
A4: 1053 | B4: Đái tháo đường
A5: 1054 | B5: Lao
A6: 1055 | B6: Hen phế quản
A7: 1056 | B7: Ung thư
A8: 1057 | B8: Động kinh
A9: 1058 | B9: Rối loạn tâm thần
A10: 1059 | B10: Bệnh khác

Sheet version
A1: 13 | B1: 1

Sheet DoiTuongKham
A1: Mã | B1: Đối Tượng
A2: 1 | B2: Sinh Viên, học viên | C2: Bắt buộc nhập 1 trong 3 đối tượng này
A3: 2 | B3: Người lao động chính thức (theo pháp luật về an toàn, vệ sinh lao động)
A4: 3 | B4: Người lao động phi chính thức
A5: 6 | B5: Người khuyết tật
A6: 7 | B6: Người thuộc hộ nghèo, cận nghèo
A7: 8 | B7: Người có công
A8: 9 | B8: Người mắc bệnh mạn tính
A9: 10 | B9: Người sống tại vùng đồng bào dân tộc thiểu số và miền núi
A10: 11 | B10: Người sống tại vùng có điều kiện kinh tế - xã hội khó khăn, đặc biệt khó khăn
A11: 12 | B11: Người sống tại xã đảo
A12: 13 | B12: Người sống tại đặc khu
A13: 19 | B13: Nhân khẩu đặc biệt

Sheet Tinh
A1: CityName | B1: CityId | C1: CityCode
A2: Tỉnh Cà Mau | B2: 63 | C2: 96
A3: Thành phố Cần Thơ | B3: 59 | C3: 92
A4: Tỉnh An Giang | B4: 57 | C4: 91
A5: Tỉnh Đồng Tháp | B5: 56 | C5: 82
A6: Tỉnh Vĩnh Long | B6: 55 | C6: 86
A7: Thành Phố Hồ Chí Minh | B7: 50 | C7: 79
A8: Tỉnh Đồng Nai | B8: 48 | C8: 75
A9: Tỉnh Tây Ninh | B9: 46 | C9: 80
A10: Tỉnh Lâm Đồng | B10: 44 | C10: 68
A11: Tỉnh Đắk Lắk | B11: 42 | C11: 66
A12: Tỉnh Gia Lai | B12: 41 | C12: 52
A13: Tỉnh Khánh Hòa | B13: 37 | C13: 56
... A35: Thành phố Hà Nội | B35: 1 | C35: 1

Sheet PhuongXa
A1: WardName | B1: WardId | C1: WardCode | D1: CityId
A2: Phường Bạc Liêu | B2: 3257 | C2: 31825 | D2: 63
A3: Phường Vĩnh Trạch | B3: 3258 | C3: 31834 | D3: 63
A4: Phường Hiệp Thành | B4: 3259 | C4: 31840 | D4: 63
A5: Xã Hồng Dân | B5: 3260 | C5: 31843 | D5: 63
A6: Xã Ninh Quới | B6: 3261 | C6: 31849 | D6: 63
A7: Xã Vĩnh Lộc | B7: 3262 | C7: 31858 | D7: 63
A8: Xã Ninh Thạnh Lợi | B8: 3263 | C8: 31864 | D8: 63
A9: Xã Phước Long | B9: 3264 | C9: 31867 | D9: 63
A10: Xã Vĩnh Phước | B10: 3265 | C10: 31876 | D10: 63
A11: Xã Vĩnh Thanh | B11: 3266 | C11: 31882 | D11: 63
A12: Xã Phong Hiệp | B12: 3267 | C12: 31885 | D12: 63
A13: Xã Hòa Bình | B13: 3268 | C13: 31891 | D13: 63
... A3322: Xã Hòa Lạc | B3322: 294 | C3322: 9988 | D3322: 1

Sheet NgheNghiep
A1: Nghề Nghiệp | B1: Mã
A2: Tổng Bí thư, Thường trực Ban Bí thư, Ban Bí thư, Ủy viên Bộ Chính trị, Ủy viên Ban Chấp hành Trung ương Đảng | B2: 227
A3: Bí thư, Phó Bí thư Đảng ủy cơ quan trung ương | B3: 228
A4: Bí thư, Phó Bí thư Đảng ủy khối trực thuộc trung ương | B4: 229
A5: Trưởng ban, Phó Trưởng ban Đảng và tương đương thuộc cấp trung ương | B5: 230
A6: Trợ lý Ủy viên Bộ Chính trị | B6: 231
A7: Vụ trưởng, Phó Vụ trưởng và tương đương | B7: 232
A8: Bí thư Tỉnh ủy, Phó Bí thư Tỉnh ủy, Ủy viên Ban Chấp hành Đảng bộ cấp tỉnh | B8: 233
A9: Bí thư, Phó Bí thư Đảng ủy sở, ban, ngành cấp tỉnh | B9: 234
A10: Bí thư, Phó Bí thư Đảng ủy khối cơ quan cấp tỉnh | B10: 235
A11: Trưởng ban, Phó Trưởng ban Đảng và tương đương thuộc cấp tỉnh | B11: 236
A12: Bí thư Huyện ủy, Phó Bí thư Huyện ủy, Ủy viên Ban Chấp hành Đảng bộ cấp huyện | B12: 237
A13: Bí thư, Phó Bí thư Đảng ủy ban, ngành cấp huyện | B13: 238
... A410: Nhân viên hướng dẫn công viên chủ đề | B410: 634
A411: Nhân viên hướng dẫn du lịch khác (như di tích lịch sử,
A413: Đầu bếp | B413: 636
A414: Tổ trưởng/Giám sát bồi bàn | B414: 637
A415: Bồi bàn (trừ bồi bàn rượu) | B415: 638
A416: Bồi bàn rượu | B416: 639
A417: Nhân viên pha chế | B417: 640
A418: Thợ làm đầu | B418: 641
A419: Nhân viên làm đẹp và nhân viên có liên quan | B419: 642
A420: Người giám sát việc dọn dẹp và vệ sinh trong văn phòng, khách sạn và các cơ quan khác | B420: 643
A421: Người quản lý công việc gia đình | B421: 644
A422: Người chăm sóc, bảo vệ tòa nhà | B422: 645
A423: Nhà chiêm tinh, nhà tướng số và những người có liên quan đến tâm linh khác | B423: 646
A424: Người bồi phòng và những người được thuê để làm bầu bạn | B424: 647
... A795: Sinh viên | B795: 2023

Sheet NoiLamViec
A1: Nơi làm việc | B1: Mã
A2: =IF(DynamicData!M3="","",DynamicData!M3) -> Phòng khám đa khoa thuộc Phòng khám đa khoa DHA Healthcare (thuộc Công ty Cổ phần Thương mại Dịch vụ Y tế DHA) | B2: =IF(DynamicData!N3="","",DynamicData!N3) -> 7
A3: =IF(DynamicData!M4="","",DynamicData!M4) -> Phòng khám đa khoa thuộc Công ty TNHH Dym Medical Center Việt Nam | B3: =IF(DynamicData!N4="","",DynamicData!N4) -> 8
A4: =IF(DynamicData!M5="","",DynamicData!M5) -> PHÒNG KHÁM ĐA KHOA THUỘC PHÒNG KHÁM ĐA KHOA HOA SEN | B4: =IF(DynamicData!N5="","",DynamicData!N5) -> 9
A5: =IF(DynamicData!M6="","",DynamicData!M6) -> Phòng khám đa khoa Intermec - Chi nhánh Công ty TNHH Phòng khám đa khoa Intermec | B5: =IF(DynamicData!N6="","",DynamicData!N6) -> 10
A6: =IF(DynamicData!M7="","",DynamicData!M7) -> Phòng khám đa khoa thuộc Công ty TNHH Phòng khám đa khoa Quốc tế | B6: =IF(DynamicData!N7="","",DynamicData!N7) -> 11
A7: =IF(DynamicData!M8="","",DynamicData!M8) -> Phòng khám Careplus Quận 1 - Chi nhánh Công ty TNHH Cityclinic Việt Nam | B7: =IF(DynamicData!N8="","",DynamicData!N8) -> 12
A8: =IF(DynamicData!M9="","",DynamicData!M9) -> Phòng khám đa khoa thuộc Địa điểm kinh doanh Phòng khám đa khoa REVIV - Chi nhánh Công ty Cổ phần Y khoa Quốc tế HTH | B8: =IF(DynamicData!N9="","",DynamicData!N9) -> 13
A9: =IF(DynamicData!M10="","",DynamicData!M10) -> Phòng khám đa khoa thuộc Công ty Cổ phần Phòng khám đa khoa Việt Gia | B9: =IF(DynamicData!N10="","",DynamicData!N10) -> 14
A10: =IF(DynamicData!M11="","",DynamicData!M11) -> Phòng khám đa khoa Quốc tế International Clinic IVY Health - Địa điểm kinh doanh số 01 - Công ty Cổ phần Y tế Prime Health | B10: =IF(DynamicData!N11="","",DynamicData!N11) -> 15
A11: =IF(DynamicData!M12="","",DynamicData!M12) -> Phòng khám đa khoa SCT Hồ Chí Minh - Chi nhánh Công ty Cổ phần Y tế SCT | B11: =IF(DynamicData!N12="","",DynamicData!N12) -> 16
A12: =IF(DynamicData!M13="","",DynamicData!M13) -> Phòng khám đa khoa thuộc Công ty Cổ phần Phòng khám Bệnh viện Quốc tế Mỹ | B12: =IF(DynamicData!N13="","",DynamicData!N13) -> 17
A13: =IF(DynamicData!M14="","",DynamicData!M14) -> Phòng khám đa khoa thuộc Công ty Cổ phần Viện Chống Lão Hóa Tế Bào Dripcare | B13: =IF(DynamicData!N14="","",DynamicData!N14) -> 18
... A20000: =IF(DynamicData!M20001="","",DynamicData!M20001) | B20000: =IF(DynamicData!N20001="","",DynamicData!N20001)

Sheet DynamicData
A1: DoiTuong_Id | B1: DoiTuong_Ten | C1: DoiTuongKham | D1: DiaDiemKham_Id | E1: DanToc | F1: DanToc_ID | G1: HinhThucChiTra | H1: HinhThucChiTra_Id | I1: HinhThucKham | J1: HinhThucKham_Id | K1: BenhTienSuGiaDinh_Id | L1: BenhTienSuGiaDinh_Name | M1: NoiLamViec | N1: NoiLamViec_Id | O1: NgheNghiep | P1: Nghề nghiệp code | Q1: DeNghi | R1: DeNghi_Id
A2: 1 | B2: Sinh Viên, học viên | C2: 4052 | D2: Cơ Sở Khám Chữa Bệnh | E2: 15 | F2: Kinh | G2: 4039 | H2: Ngân sách thành phố hỗ trợ | I2: 5083 | J2: Khám Theo Hợp Đồng | K2: 1051 | L2: Truyền nhiễm | M2: Phòng khám đa khoa thuộc Công ty Cổ phần Phòng khám Gia đình Thành phố Hồ Chí Minh (Phòng khám số 1) | N2: 6 | O2: Tổng Bí thư, Thường trực Ban Bí thư, Ban Bí thư, Ủy viên Bộ Chính trị, Ủy viên Ban Chấp hành Trung ương Đảng | P2: 227 | Q2: Bình thường, hẹn khám định kỳ lần sau | R2: 5172
A3: 2 | B3: Người lao động chính thức (theo pháp luật về an toàn, vệ sinh lao động) | C3: 4053 | D3: Khám Lưu Động | E3: 16 | F3: Tày | G3: 4040 | H3: Người sử dụng lao động chi trả | I3: 5084 | J3: Khám Phi Địa Giới | K3: 1052 | L3: Tim mạch | M3: Phòng khám đa khoa thuộc Phòng khám đa khoa DHA Healthcare (thuộc Công ty Cổ phần Thương mại Dịch vụ Y tế DHA) | N3: 7 | O3: Bí thư, Phó Bí thư Đảng ủy cơ quan trung ương | P3: 228 | Q3: Có yếu tố nguy cơ, cần theo dõi thêm | R3: 5173
A4: 3 | B4: Người lao động phi chính thức | C4: 5057 | D4: Trạm Y Tế | E4: 17 | F4: Thái | G4: 4041 | H4: Người dân tự chi trả | I4: 5133 | J4: Tự Thực hiện | K4: 1053 | L4: Đái tháo đường | M4: Phòng khám đa khoa thuộc Công ty TNHH Dym Medical Center Việt Nam | N4: 8 | O4: Bí thư, Phó Bí thư Đảng ủy khối trực thuộc trung ương | P4: 229 | Q4: Đã có bệnh mạn tính, tiếp tục điều trị theo phác đồ/toa cũ | R4: 5174
A5: 6 | B5: Người khuyết tật | C5: 5060 | D5: KSK Tại Nhà | E5: 18 | F5: Hoa | G5: 4042 | H5: Nguồn khác | K5: 1054 | L5: Lao | M5: PHÒNG KHÁM ĐA KHOA THUỘC PHÒNG KHÁM ĐA KHOA HOA SEN | N5: 9 | O5: Trưởng ban, Phó Trưởng ban Đảng và tương đương thuộc cấp trung ương | P5: 230 | Q5: Chuyển tuyến, khám chuyên khoa | R5: 5175
A6: 7 | B6: Người thuộc hộ nghèo, cận nghèo | C6: 5131 | D6: Trường Học | E6: 19 | F6: Khme | K6: 1055 | L6: Hen phế quản | M6: Phòng khám đa khoa Intermec - Chi nhánh Công ty TNHH Phòng khám đa khoa Intermec | N6: 10 | O6: Trợ lý Ủy viên Bộ Chính trị | P6: 231 | Q6: Khác | R6: 5176
A7: 8 | B7: Người có công | E7: 20 | F7: Mường | K7: 1056 | L7: Ung thư | M7: Phòng khám đa khoa thuộc Công ty TNHH Phòng khám đa khoa Quốc tế | N7: 11 | O7: Vụ trưởng, Phó Vụ trưởng và tương đương | P7: 232
A8: 9 | B8: Người mắc bệnh mạn tính | E8: 21 | F8: Nùng | K8: 1057 | L8: Động kinh | M8: Phòng khám Careplus Quận 1 - Chi nhánh Công ty TNHH Cityclinic Việt Nam | N8: 12 | O8: Bí thư Tỉnh ủy, Phó Bí thư Tỉnh ủy, Ủy viên Ban Chấp hành Đảng bộ cấp tỉnh | P8: 233
A9: 10 | B9: Người sống tại vùng đồng bào dân tộc thiểu số và miền núi | E9: 22 | F9: Hán | K9: 1058 | L9: Rối loạn tâm thần | M9: Phòng khám đa khoa thuộc Địa điểm kinh doanh Phòng khám đa khoa REVIV - Chi nhánh Công ty Cổ phần Y khoa Quốc tế HTH | N9: 13 | O9: Bí thư, Phó Bí thư Đảng ủy sở, ban, ngành cấp tỉnh | P9: 234
A10: 11 | B10: Người sống tại vùng có điều kiện kinh tế - xã hội khó khăn, đặc biệt khó khăn | E10: 23 | F10: Dao | K10: 1059 | L10: Bệnh khác | M10: Phòng khám đa khoa thuộc Công ty Cổ phần Phòng khám đa khoa Việt Gia | N10: 14 | O10: Bí thư, Phó Bí thư Đảng ủy khối cơ quan cấp tỉnh | P10: 235
A11: 12 | B11: Người sống tại xã đảo | E11: 24 | F11: Gia rai | M11: Phòng khám đa khoa Quốc tế International Clinic IVY Health - Địa điểm kinh doanh số 01 - Công ty Cổ phần Y tế Prime Health | N11: 15 | O11: Trưởng ban, Phó Trưởng ban Đảng và tương đương thuộc cấp tỉnh | P11: 236
A12: 13 | B12: Người sống tại đặc khu | E12: 25 | F12: Cao lan | M12: Phòng khám đa khoa SCT Hồ Chí Minh - Chi nhánh Công ty Cổ phần Y tế SCT | N12: 16 | O12: Bí thư Huyện ủy, Phó Bí thư Huyện ủy, Ủy viên Ban Chấp hành Đảng bộ cấp huyện | P12: 237
A13: 19 | B13: Nhân khẩu đặc biệt | E13: 26 | F13: Ê đê | M13: Phòng khám đa khoa thuộc Công ty Cổ phần Phòng khám Bệnh viện Quốc tế Mỹ | N13: 17 | O13: Bí thư, Phó Bí thư Đảng ủy ban, ngành cấp huyện | P13: 238
E14: 27 | F14: Ba na | M14: Phòng khám đa khoa thuộc Công ty Cổ phần Viện Chống Lão Hóa Tế Bào Dripcare | N14: 18 | O14: Trưởng ban, Phó Trưởng ban Đảng và tương đương thuộc cấp huyện | P14: 239
E15: 28 | F15: Xơ đăng | M15: Phòng khám đa khoa thuộc Chi nhánh Công ty TNHH Phòng khám đa khoa Quốc Tế Sài Gòn | N15: 19 | O15: Bí thư, Phó Bí thư Đảng ủy cấp xã | P15: 240
E16: 29 | F16: Sán Chay | M16: Phòng khám đa khoa thuộc Bệnh viện Đa khoa Tân Định (Cơ sở 2) | N16: 20 | O16: Bí thư, Phó Bí thư Đảng ủy | P16: 241
E17: 30 | F17: Cơ ho | M17: Phòng khám đa khoa thuộc Trạm y tế phường Tân Định | N17: 21 | O17: Chủ tịch Quốc hội, Phó Chủ tịch Quốc hội, Ủy viên thường vụ Quốc hội | P17: 242
E18: 31 | F18: Chăm | M18: Phòng khám đa khoa thuộc Công ty cổ phần Y khoa Vietmedi | N18: 22 | O18: Chủ nhiệm, Phó Chủ nhiệm Ủy ban và tương đương làm việc tại Văn phòng Quốc hội | P18: 243
E19: 32 | F19: Sán chỉ | M19: Phòng khám đa khoa thuộc Chi nhánh Công ty Cổ phần Đầu tư 3H - Phòng khám đa khoa Quốc tế Yersin | N19: 24 | O19: Vụ trưởng, Phó Vụ trưởng và tương đương | P19: 244
E20: 33 | F20: Hrê | M20: Phòng khám đa khoa thuộc Công ty TNHH Dịch vụ Chăm sóc sức khỏe Song An | N20: 25 | O20: Chủ tịch nước, Phó Chủ tịch nước | P20: 245
E21: 34 | F21: M nông | M21: Phòng khám đa khoa thuộc Chi nhánh Công ty TNHH Phòng khám đa khoa Sài Gòn - Trung tâm khám bệnh số 2 | N21: 26 | O21: Chủ nhiệm, Phó Chủ nhiệm tương đương Bộ trưởng, Thứ trưởng và tương đương làm việc tại Văn phòng Chủ tịch nước | P21: 246
E22: 35 | F22: Raglai | M22: Phòng khám đa khoa thuộc Công ty TNHH Y tế Minh Khai | N22: 27 | O22: Vụ trưởng, Phó Vụ trưởng và tương đương | P22: 247
E23: 36 | F23: Xtiêng | M23: Phòng khám đa khoa thuộc Công ty Cổ phần Vinamedical - Trung tâm Y khoa Sài Gòn | N23: 28 | O23: Thủ tướng, Phó Thủ tướng Chính phủ | P23: 248
E24: 37 | F24: Bru (Khùa) | M24: Phòng khám đa khoa thuộc Công ty Cổ phần Bệnh viện PACIFIC | N24: 29 | O24: Chủ nhiệm, Phó Chủ nhiệm và tương đương làm việc tại Văn phòng Chính phủ | P24: 249
E25: 38 | F25: Thổ | M25: Phòng khám đa khoa thuộc Công ty Cổ phần Vigor Health (tên cũ: Công ty TNHH Vigor Health) | N25: 30 | O25: Vụ trưởng, Phó Vụ trưởng và tương đương | P25: 250
... E79: 1040 | F79: Khác trong nước | M79: Phòng khám đa khoa thuộc Công ty TNHH Phòng khám đa khoa Sài Gòn Tân Thuận | N79: 85 | O79: Khai khoáng, công nghiệp chế biến, chế tạo, sản xuất và phân phối điện, khí đốt, nước nóng, hơi nước và điều hòa không khí | P79: 304
M80: Phòng khám đa khoa thuộc Công ty TNHH Phòng khám đa khoa Trí Việt (tên cũ: Công ty TNHH Phòng khám đa khoa Tân Mỹ) | N80: 86 | O80: Xây dựng | P80: 305
M81: Phòng khám đa khoa Singapore Indochina Healthcare Group thuộc Công ty Trách nhiệm hữu hạn Singapore Indochina Healthcare Group | N81: 87 | O81: Bán buôn, bán lẻ | P81: 306
M82: Phòng khám đa khoa thuộc Trạm y tế phường Tân Mỹ | N82: 88 | O82: Dịch vụ lưu trú và ăn uống | P82: 307
M83: Phòng khám đa khoa thuộc Công ty TNHH Phòng khám đa khoa Liên Tâm | N83: 89 | O83: Vận tải kho bãi; Thông tin và truyền thông | P83: 308
M84: Phòng khám đa khoa quốc tế Leancare (thuộc Công ty cổ phần giải pháp chăm sóc sức khỏe Tâm Hợp) | N84: 90 | O84: Dịch vụ kinh doanh | P84: 309
M85: Phòng khám đa khoa thuộc Bệnh viện Đa khoa Chánh Hưng - Cơ sở 2 (Phòng khám đa khoa Xóm Củi) | N85: 91 | O85: Dịch vụ cá nhân và cộng đồng | P85: 310
M86: Phòng khám đa khoa thuộc Trạm y tế phường Bình Đông | N86: 92 | O86: Các đơn vị sản xuất và dịch vụ còn lại chưa được phân vào đâu | P86: 311
M87: Phòng khám đa khoa thuộc Địa điểm kinh doanh Công ty TNHH Phòng khám đa khoa Quốc tế Việt Healthcare | N87: 93 | O87: Nhà vật lý học và thiên văn học | P87: 312
M88: Phòng khám đa khoa - Trung tâm Xét nghiệm và Chẩn đoán Y khoa - Medical Diag Center | N88: 94 | O88: Nhà khí tượng học | P88: 313
M89: Phòng khám đa khoa thuộc Công ty TNHH Y tế Hòa Hảo | N89: 95 | O89: Nhà hóa học | P89: 314
M90: Phòng khám đa khoa thuộc Công ty Cổ phần bệnh viện KingDom | N90: 96 | O90: Nhà địa chất, địa vật lý | P90: 315
M91: Phòng khám đa khoa thuộc Địa điểm kinh doanh Thành phố Hồ Chí Minh - Công ty Cổ phần Thương Mại và Đầu tư 3T | N91: 97 | O91: Nhà toán học | P91: 316
... M793: MNĐL NGÂN KHÁNH | N793: 807 | O793: Sinh viên | P793: 2023
M794: MNDL NGÂN KHÁNH | N794: 808
...
